22-03-2025 at 16:09:42 | ERROR | An error has been caught in function '<module>', process 'MainProcess' (87133), thread 'MainThread' (4569013696):
Traceback (most recent call last):

> File "/Users/user/PythonProjects/Numerolog_free/src/star", line 76, in <module>
    main()
    └ <function main at 0x10df03380>
  File "/Users/user/PythonProjects/Numerolog_free/src/star", line 64, in main
    result = create_star_report(union_star_data)
             │                  └ [[TextElement(position=(74.97, 22.3146), text='Julia 23.07.1982', font={'name': 'roboto_regular', 'style': '', 'size': 21.168...
             └ <function create_star_report at 0x10df03420>

  File "/Users/user/PythonProjects/Numerolog_free/reports/pdf_creator.py", line 28, in create_star_report
    star_image_content = generate_pdf(
                         └ <function generate_pdf at 0x10df03600>

  File "/Users/user/PythonProjects/Numerolog_free/reports/pdf_creator.py", line 49, in generate_pdf
    pdf.create_text_pages(text_data)
    │   │                 └ TextPageData(background_color=None, text_color=(230, 223, 210), sections=[<class 'report_storage.report_classes.Section'>, <c...
    │   └ <function CustomPDF.create_text_pages at 0x10df03880>
    └ <reports.pdf_utility.CustomPDF object at 0x10da2ea50>

  File "/Users/user/PythonProjects/Numerolog_free/reports/pdf_utility.py", line 65, in create_text_pages
    self.set_fill_color(*page_data.background_color)
    │    │               │         └ None
    │    │               └ TextPageData(background_color=None, text_color=(230, 223, 210), sections=[<class 'report_storage.report_classes.Section'>, <c...
    │    └ <function FPDF.set_fill_color at 0x10defd8a0>
    └ <reports.pdf_utility.CustomPDF object at 0x10da2ea50>

TypeError: fpdf.fpdf.FPDF.set_fill_color() argument after * must be an iterable, not NoneType
22-03-2025 at 16:32:56 | ERROR | An error has been caught in function '<module>', process 'MainProcess' (92483), thread 'MainThread' (4495842752):
Traceback (most recent call last):

> File "/Users/user/PythonProjects/Numerolog_free/src/star", line 76, in <module>
    main()
    └ <function main at 0x1053f7420>
  File "/Users/user/PythonProjects/Numerolog_free/src/star", line 64, in main
    result = create_star_report(union_star_data)
             │                  └ [[TextElement(position=(74.97, 22.3146), text='Julia 23.07.1982', font={'name': 'roboto_regular', 'style': '', 'size': 21.168...
             └ <function create_star_report at 0x1053f74c0>

  File "/Users/user/PythonProjects/Numerolog_free/reports/pdf_creator.py", line 28, in create_star_report
    star_image_content = generate_pdf(
                         └ <function generate_pdf at 0x1053f76a0>

  File "/Users/user/PythonProjects/Numerolog_free/reports/pdf_creator.py", line 49, in generate_pdf
    pdf.create_text_pages(text_data)
    │   │                 └ TextPageData(background_color=(227, 221, 208), text_color=(230, 223, 210), sections=[<class 'report_storage.report_classes.Se...
    │   └ <function CustomPDF.create_text_pages at 0x1053f7920>
    └ <reports.pdf_utility.CustomPDF object at 0x104f22a50>

  File "/Users/user/PythonProjects/Numerolog_free/reports/pdf_utility.py", line 81, in create_text_pages
    self.set_font("DejaVu", "", 18)
    │    └ <function FPDF.set_font at 0x1053f2160>
    └ <reports.pdf_utility.CustomPDF object at 0x104f22a50>

  File "/Users/user/PythonProjects/Numerolog_free/.venv/lib/python3.13/site-packages/fpdf/fpdf.py", line 603, in set_font
    self.error('Undefined font: '+family+' '+style)
    │    │                        │          └ ''
    │    │                        └ 'dejavu'
    │    └ <function FPDF.error at 0x1053f13a0>
    └ <reports.pdf_utility.CustomPDF object at 0x104f22a50>
  File "/Users/user/PythonProjects/Numerolog_free/.venv/lib/python3.13/site-packages/fpdf/fpdf.py", line 227, in error
    raise RuntimeError('FPDF error: '+msg)
                                      └ 'Undefined font: dejavu '

RuntimeError: FPDF error: Undefined font: dejavu 
22-03-2025 at 16:36:00 | ERROR | An error has been caught in function '<module>', process 'MainProcess' (93164), thread 'MainThread' (4672806336):
Traceback (most recent call last):

> File "/Users/user/PythonProjects/Numerolog_free/src/star", line 76, in <module>
    main()
    └ <function main at 0x109b2f380>
  File "/Users/user/PythonProjects/Numerolog_free/src/star", line 64, in main
    result = create_star_report(union_star_data)
             │                  └ [[TextElement(position=(74.97, 22.3146), text='Julia 23.07.1982', font={'name': 'roboto_regular', 'style': '', 'size': 21.168...
             └ <function create_star_report at 0x109b2f420>

  File "/Users/user/PythonProjects/Numerolog_free/reports/pdf_creator.py", line 28, in create_star_report
    star_image_content = generate_pdf(
                         └ <function generate_pdf at 0x109b2f600>

  File "/Users/user/PythonProjects/Numerolog_free/reports/pdf_creator.py", line 49, in generate_pdf
    pdf.create_text_pages(text_data)
    │   │                 └ TextPageData(background_color=(227, 221, 208), text_color=(230, 223, 210), sections=[<class 'report_storage.report_classes.Se...
    │   └ <function CustomPDF.create_text_pages at 0x109b2f880>
    └ <reports.pdf_utility.CustomPDF object at 0x109656a50>

  File "/Users/user/PythonProjects/Numerolog_free/reports/pdf_utility.py", line 90, in create_text_pages
    for info_item in section.info:
                     └ <class 'report_storage.report_classes.Section'>

AttributeError: type object 'Section' has no attribute 'info'
22-03-2025 at 20:35:52 | ERROR | An error has been caught in function '<module>', process 'MainProcess' (45396), thread 'MainThread' (4679880128):
Traceback (most recent call last):

> File "/Users/user/PythonProjects/Numerolog_free/src/star", line 76, in <module>
    main()
    └ <function main at 0x10d567420>
  File "/Users/user/PythonProjects/Numerolog_free/src/star", line 64, in main
    result = create_star_report(union_star_data)
             │                  └ [[TextElement(position=(74.97, 22.3146), text='Julia 23.07.1982', font={'name': 'roboto_regular', 'style': '', 'size': 21.168...
             └ <function create_star_report at 0x10d5674c0>

  File "/Users/user/PythonProjects/Numerolog_free/reports/pdf_creator.py", line 28, in create_star_report
    star_image_content = generate_pdf(
                         └ <function generate_pdf at 0x10d567740>

  File "/Users/user/PythonProjects/Numerolog_free/reports/pdf_creator.py", line 49, in generate_pdf
    pdf.create_text_pages(text_data)
    │   │                 └ TextPageData(background_color=(12, 24, 46), text_color=(221, 248, 248), sections=[Section(title='Личность', subtitle='Положит...
    │   └ <function CustomPDF.create_text_pages at 0x10d5679c0>
    └ <reports.pdf_utility.CustomPDF object at 0x10d11aba0>

  File "/Users/user/PythonProjects/Numerolog_free/reports/pdf_utility.py", line 82, in create_text_pages
    if old_title != section.title():
       │            │       └ 'Личность'
       │            └ Section(title='Личность', subtitle='Положительные черты:', info=['Умеренный консерватизм,', 'Чтят традиции, нормы и устои, пр...
       └ ''

TypeError: 'str' object is not callable
22-03-2025 at 20:47:27 | ERROR | An error has been caught in function '<module>', process 'MainProcess' (48160), thread 'MainThread' (4493962688):
Traceback (most recent call last):

> File "/Users/user/PythonProjects/Numerolog_free/src/star", line 76, in <module>
    main()
    └ <function main at 0x107263420>
  File "/Users/user/PythonProjects/Numerolog_free/src/star", line 64, in main
    result = create_star_report(union_star_data)
             │                  └ [[TextElement(position=(74.97, 22.3146), text='Julia 23.07.1982', font={'name': 'roboto_regular', 'style': '', 'size': 21.168...
             └ <function create_star_report at 0x1072634c0>

  File "/Users/user/PythonProjects/Numerolog_free/reports/pdf_creator.py", line 28, in create_star_report
    star_image_content = generate_pdf(
                         └ <function generate_pdf at 0x107263740>

  File "/Users/user/PythonProjects/Numerolog_free/reports/pdf_creator.py", line 49, in generate_pdf
    pdf.create_text_pages(text_data)
    │   │                 └ TextPageData(background_color=(12, 24, 46), text_color=(221, 248, 248), sections=[Section(title='Личность', subtitle='Положит...
    │   └ <function CustomPDF.create_text_pages at 0x1072639c0>
    └ <reports.pdf_utility.CustomPDF object at 0x106e16ba0>

  File "/Users/user/PythonProjects/Numerolog_free/reports/pdf_utility.py", line 121, in create_text_pages
    self.ln(self.font_size) * 0.6
    │    │  │    └ 3.5277777777777772
    │    │  └ <reports.pdf_utility.CustomPDF object at 0x106e16ba0>
    │    └ <function FPDF.ln at 0x107256d40>
    └ <reports.pdf_utility.CustomPDF object at 0x106e16ba0>

TypeError: unsupported operand type(s) for *: 'NoneType' and 'float'
